Workbook
Name lstAlertas: PARAMETROS!$A$24:$A$30
Name lstDocentes: _xlfn.ANCHORARRAY(PARAMETROS!$H$5)
Name lstDocentesAlertas: _xlfn.ANCHORARRAY(PARAMETROS!$K$5)
Name lstEstados: PARAMETROS!$A$18:$A$21
Name lstGrupos: _xlfn.ANCHORARRAY(PARAMETROS!$I$5)
Name lstGruposCurso: _xlfn.ANCHORARRAY(PARAMETROS!$J$5)
Name lstProgramas: _xlfn.ANCHORARRAY(PARAMETROS!$G$5)
Name pCaidaTend: PARAMETROS!$B$13
Name pDesvAnom: PARAMETROS!$B$14
Name pFaltasConsec: PARAMETROS!$B$11
Name pPrueba: PARAMETROS!$B$15
Name pVentanaTend: PARAMETROS!$B$12

Sheet INICIO
B1: SEGUIMIENTO DE ASISTENCIA ACADÉMICA — ESTUD-IA
B2: ="Asistencia calculada sobre clases dictadas · Fuente: hoja Estudiantes ("&ROWS(tblMatriculas[Cédula])&" matrículas) · Umbrales en PARAMETROS" -> Asistencia calculada sobre clases dictadas · Fuente: hoja Estudiantes (2127 matrículas) · Umbrales en PARAMETROS
B3: ▸ CURSOS | C3: ▸ FICHA ESTUDIANTE | D3: ▸ ALERTAS | E3: ▸ INCONSISTENCIAS | F3: ▸ GRUPOS | G3: ▸ DATOS | H3: ▸ PARÁMETROS
B5: Curso (programa) | C5: ANÁLISIS Y VISUALIZACIÓN DE DATOS PARA LA TOMA DE DECISIONES | F5: ="Periodo / Fecha: "&IF(COUNT(tblAsistenciaDiaria[Fecha])=0,"no disponibles — el archivo no trae fechas de asistencia. Al cargar la hoja DATOS, use los filtros de fecha en ANÁLISIS FECHA.","use los filtros Desde/Hasta en ANÁLISIS FECHA ("&DAY(MIN(tblAsistenciaDiaria[Fecha]))&"/"&MONTH(MIN(tblAsistenciaDiaria[Fecha]))&"/"&YEAR(MIN(tblAsistenciaDiaria[Fecha]))&" – "&DAY(MAX(tblAsistenciaDiaria[Fecha]))&"/"&MONTH(MAX(tblAsistenciaDiaria[Fecha]))&"/"&YEAR(MAX(tblAsistenciaDiaria[Fecha]))&").") -> Periodo / Fecha: no disponibles — el archivo no trae fechas de asistencia. Al cargar la hoja DATOS, use los filtros de fecha en ANÁLISIS FECHA. | K5: GRUPOS CON MENOR ASISTENCIA
B6: Grupo | C6: DAT-05 | K6: Grupo | L6: Docente | M6: % asist. | N6: Críticos | O6: % riesgo | P6: Nivel
B7: Docente | C7: (Todos) | K7: {=_xlfn.LET(_xlpm.k,COUNTIFS(tblGrupos[Código],tblGrupos[Código],tblGrupos[Programa],CALC!$B$3,tblGrupos[Código],CALC!$B$4,tblGrupos[Docente],CALC!$B$5)*(tblGrupos[Estudiantes evaluados]>0),_xlpm.res,_xlfn._xlws.FILTER(_xlfn.HSTACK(tblGrupos[Código],tblGrupos[Docente],tblGrupos[% asistencia],tblGrupos[Críticos],tblGrupos[% en riesgo],tblGrupos[Nivel grupo]),_xlpm.k,"Sin grupos"),_xlfn.TAKE(_xlfn.SORTBY(_xlpm.res,_xlfn.CHOOSECOLS(_xlpm.res,3),1),MIN(12,ROWS(_xlpm.res))))} -> DAT-05 | L7: Johan Muriel | M7: 0.12576923 | N7: 7 | O7: 0.17948718 | P7: 🟢 NORMAL
B9: Cursos | C9: Grupos | D9: Estudiantes activos | E9: Clases dictadas (sesiones) | F9: Asistencia promedio (sobre plan) | G9: Inasistencia (sobre clases dictadas) | H9: En riesgo (🟡+🟠) | I9: 🔴 Críticos
B10: =CALC!B9 -> 1 | C10: =CALC!B10 -> 1 | D10: =CALC!B11 -> 39 | E10: =CALC!B13 -> 5 | F10: =CALC!B16 -> 0.12576923 | G10: =CALC!B17 -> 0.25 | H10: =CALC!B18 -> 0 | I10: =CALC!B19 -> 7
B11: =CALC!B12&" matrículas" -> 39 matrículas | E11: =CALC!B14&" asistencias" -> 150 asistencias | F11: =IF(CALC!B16="","",_xlfn.XLOOKUP(ROUND(CALC!B16,3),tblNiveles[Hasta (% asistencia, incluido)],tblNiveles[Nivel],,1)) -> 🟢 NORMAL | H11: =IFERROR(ROUND(CALC!B18/CALC!B12*100,0)&"% de matrículas","") -> 0% de matrículas | I11: =IFERROR(ROUND(CALC!B19/CALC!B12*100,0)&"% · "&CALC!C25&" sin registro","") -> 18% · 0 sin registro
K19: Ver estudiantes del grupo en CURSOS →
G30: 📅 EVOLUCIÓN POR FECHA El archivo actual no trae fechas de asistencia (solo acumulados como 4/45), por lo que no se puede graficar la evolución en el tiempo.

Sheet CURSOS
B1: CURSOS — Vista por grupo
B2: Seleccione un programa y un grupo. % asistencia calculado sobre clases dictadas (ver GRUPOS). Estudiantes ordenados de menor a mayor asistencia.
B4: Programa (curso) | C4: ANÁLISIS Y VISUALIZACIÓN DE DATOS PARA LA TOMA DE DECISIONES | F4: =IFERROR(_xlfn.XLOOKUP($C$5,tblGrupos[Código],tblGrupos[Grupo]),"Grupo no encontrado") -> DAT-02 - Análisis y Visualización de Datos
B5: Grupo | C5: DAT-02 | F5: =IFERROR("Docente: "&_xlfn.XLOOKUP($C$5,tblGrupos[Código],tblGrupos[Docente])&" | "&_xlfn.XLOOKUP($C$5,tblGrupos[Código],tblGrupos[Horario]),"") -> Docente: César Diaz | Martes 18:30-21:30 | Jueves 18:30-21:30
F6: =IFERROR(_xlfn.XLOOKUP($C$5,tblGrupos[Código],tblGrupos[Programa]),"") -> ANÁLISIS Y VISUALIZACIÓN DE DATOS PARA LA TOMA DE DECISIONES
B8: Estudiantes evaluados | C8: Clases planeadas | D8: Clases dictadas | E8: Total asistencias | F8: Total inasistencias | G8: % asistencia | H8: % estudiantes en riesgo | I8: Nivel del grupo
B9: =IFERROR(_xlfn.XLOOKUP($C$5,tblGrupos[Código],tblGrupos[Estudiantes evaluados]),"") -> 51 | C9: =IFERROR(_xlfn.XLOOKUP($C$5,tblGrupos[Código],tblGrupos[Clases planeadas]),"") -> 30 | D9: =IFERROR(_xlfn.XLOOKUP($C$5,tblGrupos[Código],tblGrupos[Clases dictadas]),"") -> 4 | E9: =IFERROR(_xlfn.XLOOKUP($C$5,tblGrupos[Código],tblGrupos[Asistencias]),"") -> 173 | F9: =IFERROR(_xlfn.XLOOKUP($C$5,tblGrupos[Código],tblGrupos[Inasistencias]),"") -> 31 | G9: =IFERROR(_xlfn.XLOOKUP($C$5,tblGrupos[Código],tblGrupos[% asistencia]),"") -> 0.11294118 | H9: =IFERROR(_xlfn.XLOOKUP($C$5,tblGrupos[Código],tblGrupos[% en riesgo]),"") -> 0.039215686 | I9: =IFERROR(_xlfn.XLOOKUP($C$5,tblGrupos[Código],tblGrupos[Nivel grupo]),"") -> 🟢 NORMAL
B10: =IFERROR("Críticos: "&_xlfn.XLOOKUP($C$5,tblGrupos[Código],tblGrupos[Críticos])&" · Alerta: "&_xlfn.XLOOKUP($C$5,tblGrupos[Código],tblGrupos[Alerta])&" · Seguimiento: "&_xlfn.XLOOKUP($C$5,tblGrupos[Código],tblGrupos[Seguimiento])&" · Normal: "&_xlfn.XLOOKUP($C$5,tblGrupos[Código],tblGrupos[Normal])&" · Sin registro: "&_xlfn.XLOOKUP($C$5,tblGrupos[Código],tblGrupos[Sin registro]),"") -> Críticos: 0 · Alerta: 0 · Seguimiento: 2 · Normal: 49 · Sin registro: 0
B12: ESTUDIANTES DEL GRUPO | L12: RANKING DE GRUPOS (menor asistencia primero) — filtrado por programa
B13: Estudiante | C13: Cédula | D13: Clases dictadas | E13: Asistencias | F13: Inasistencias | G13: % Asistencia | H13: Estado | I13: Tipo de alerta | J13: Observación | L13: Código | M13: Docente | N13: Evaluados | O13: % asistencia | P13: Inasistencias | Q13: Críticos | R13: % en riesgo | S13: Nivel
B14: {=_xlfn.LET(_xlpm.k,(tblMatriculas[Código]=$C$5)*(tblMatriculas[Estado]="activa"),_xlpm.d,_xlfn.HSTACK(tblMatriculas[Nombre],tblMatriculas[Cédula],tblMatriculas[Clases dictadas],tblMatriculas[Asistidas],tblMatriculas[Inasistencias],tblMatriculas[% asistencia],tblMatriculas[Nivel],tblMatriculas[Tipo de alerta],tblMatriculas[Observación]),_xlpm.r,_xlfn._xlws.FILTER(_xlpm.d,_xlpm.k,"Sin estudiantes activos"),IFERROR(_xlfn.SORTBY(_xlpm.r,_xlfn.CHOOSECOLS(_xlpm.r,6),1,_xlfn.CHOOSECOLS(_xlpm.r,1),1),_xlpm.r))} -> JULIO CESA JULIO CESA ARAGÓN SANTOS | C14: 1040509268 | D14: 4 | E14: 2 | F14: 2 | G14: 0.067 | H14: 🟡 SEGUIMIENTO | I14: 🟡 SEGUIMIENTO | L14: {=_xlfn.LET(_xlpm.k,IF($C$4="(Todos)",tblGrupos[Código]<>"",tblGrupos[Programa]=$C$4),_xlpm.d,_xlfn.HSTACK(tblGrupos[Código],tblGrupos[Docente],tblGrupos[Estudiantes evaluados],tblGrupos[% asistencia],tblGrupos[Inasistencias],tblGrupos[Críticos],tblGrupos[% en riesgo],tblGrupos[Nivel grupo]),_xlpm.r,_xlfn._xlws.FILTER(_xlpm.d,_xlpm.k),_xlfn.SORTBY(_xlpm.r,_xlfn.CHOOSECOLS(_xlpm.r,4),1))} -> DAT-06 | M14: Alvaro Viloria | N14: 31 | O14: 0.048 | P14: 21 | Q14: 5 | R14: 1 | S14: 🟡 SEGUIMIENTO
B15: WILLIAM AUGUSTO GIL ESPINAL | C15: 71791733 | D15: 4 | E15: 2 | F15: 2 | G15: 0.067 | H15: 🟡 SEGUIMIENTO | I15: 🟡 SEGUIMIENTO | L15: DAT-09 | M15: Alvaro Viloria | N15: 27 | O15: 0.049481481 | P15: 14 | Q15: 3 | R15: 1 | S15: 🟡 SEGUIMIENTO
B16: ALEJANDRA ECHEVERRI GARZÓN | C16: 1152209669 | D16: 4 | E16: 3 | F16: 1 | G16: 0.1 | H16: 🟢 NORMAL | L16: DAT-07 | M16: César Diaz | N16: 31 | O16: 0.056096774 | P16: 10 | Q16: 2 | R16: 1 | S16: 🟡 SEGUIMIENTO
B17: ANA CRISTINA CORREA QUINTANA | C17: 1128468627 | D17: 4 | E17: 3 | F17: 1 | G17: 0.1 | H17: 🟢 NORMAL | J17: Traslado desde DAT-04 | L17: DAT-10 | M17: César Diaz | N17: 21 | O17: 0.096761905 | P17: 23 | Q17: 0 | R17: 0.42857143 | S17: 🟢 NORMAL
B18: ANDREA HOYOS ATEHORTUA | C18: 1152448697 | D18: 4 | E18: 3 | F18: 1 | G18: 0.1 | H18: 🟢 NORMAL | L18: DAT-08 | M18: Cristian Jimenez | N18: 47 | O18: 0.10976596 | P18: 33 | Q18: 0 | R18: 0.19148936 | S18: 🟢 NORMAL
B19: CRISTIAN DAVID TANGARIFE TORRES | C19: 1045018769 | D19: 4 | E19: 3 | F19: 1 | G19: 0.1 | H19: 🟢 NORMAL | L19: DAT-02 | M19: César Diaz | N19: 51 | O19: 0.11294118 | P19: 31 | Q19: 0 | R19: 0.039215686 | S19: 🟢 NORMAL
B20: DIEGO DIEGO ALVAREZ VELEZ | C20: 1000538256 | D20: 4 | E20: 3 | F20: 1 | G20: 0.1 | H20: 🟢 NORMAL | L20: DAT-04 | M20: Alvaro Viloria | N20: 42 | O20: 0.12114286 | P20: 60 | Q20: 5 | R20: 0.26190476 | S20: 🟢 NORMAL
B21: JAIME ALBERTO GALLO BLANDÓN | C21: 8060326 | D21: 4 | E21: 3 | F21: 1 | G21: 0.1 | H21: 🟢 NORMAL | L21: DAT-05 | M21: Johan Muriel | N21: 39 | O21: 0.12576923 | P21: 50 | Q21: 7 | R21: 0.17948718 | S21: 🟢 NORMAL
B22: JESUS ARMANDO CALVO BARRAZA | C22: 1129566292 | D22: 4 | E22: 3 | F22: 1 | G22: 0.1 | H22: 🟢 NORMAL | L22: DAT-03 | M22: Cristian Jimenez | N22: 50 | O22: 0.14474 | P22: 83 | Q22: 6 | R22: 0.2 | S22: 🟢 NORMAL
B23: JOSE EDUARDO GONZALEZ BERMUDEZ | C23: 1039452612 | D23: 4 | E23: 3 | F23: 1 | G23: 0.1 | H23: 🟢 NORMAL | J23: Traslado desde DAT-05 | L23: DAT-01 | M23: Carlos Duran | N23: 38 | O23: 0.15028947 | P23: 85 | Q23: 0 | R23: 0.15789474 | S23: 🟢 NORMAL
B24: JUAN CAMILO ARIAS CARMONA | C24: 1022363737 | D24: 4 | E24: 3 | F24: 1 | G24: 0.1 | H24: 🟢 NORMAL | J24: Traslado desde DAT-09
B25: JUAN CAMILO RENDON VELEZ | C25: 1036630549 | D25: 4 | E25: 3 | F25: 1 | G25: 0.1 | H25: 🟢 NORMAL
B26: KAATHERINE LÓPEZ ARBOLEDA | C26: 1017217793 | D26: 4 | E26: 3 | F26: 1 | G26: 0.1 | H26: 🟢 NORMAL
B27: KELLY JOHANA SALGADO SALGADO | C27: 32243764 | D27: 4 | E27: 3 | F27: 1 | G27: 0.1 | H27: 🟢 NORMAL
B28: LAURA VASCO PEREZ | C28: 1017242197 | D28: 4 | E28: 3 | F28: 1 | G28: 0.1 | H28: 🟢 NORMAL
B29: LINDA DIANELLA MAHECHA BUSTOS | C29: 1002604580 | D29: 4 | E29: 3 | F29: 1 | G29: 0.1 | H29: 🟢 NORMAL
B30: MARCIAL FERNEY TORRES ORTEGA | C30: 1099542769 | D30: 4 | E30: 3 | F30: 1 | G30: 0.1 | H30: 🟢 NORMAL
B31: MARIANA VILLEGAS BOLIVAR | C31: 1020116853 | D31: 4 | E31: 3 | F31: 1 | G31: 0.1 | H31: 🟢 NORMAL
B32: MARILIN ALEJANDRA ALZATE ZAPATA | C32: 1127954791 | D32: 4 | E32: 3 | F32: 1 | G32: 0.1 | H32: 🟢 NORMAL
B33: MARLIN YULIET BELTRAN VALENCIA | C33: 32207484 | D33: 4 | E33: 3 | F33: 1 | G33: 0.1 | H33: 🟢 NORMAL
B34: SEBASTIÁN OBREGÓN SILVA | C34: 1007827747 | D34: 4 | E34: 3 | F34: 1 | G34: 0.1 | H34: 🟢 NORMAL | J34: Traslado desde DAT-05
B35: SIMÓN PAREDES RIVERA | C35: 1000290485 | D35: 4 | E35: 3 | F35: 1 | G35: 0.1 | H35: 🟢 NORMAL
B36: STEPHANY STEPHANY CEBALLOS DIEZ | C36: 1216713555 | D36: 4 | E36: 3 | F36: 1 | G36: 0.1 | H36: 🟢 NORMAL
B37: WILLIAM RAFAEL CASTRO AGUAS | C37: 1100392465 | D37: 4 | E37: 3 | F37: 1 | G37: 0.1 | H37: 🟢 NORMAL
B38: YENERIS ANDREA DE LA OSSA RAMOS | C38: 1038100957 | D38: 4 | E38: 3 | F38: 1 | G38: 0.1 | H38: 🟢 NORMAL
B39: YESID FARID JIMENEZ RIVERO | C39: 1214742749 | D39: 4 | E39: 3 | F39: 1 | G39: 0.1 | H39: 🟢 NORMAL
B40: YICELY DIAZ TAPIAS | C40: 1146434324 | D40: 4 | E40: 3 | F40: 1 | G40: 0.1 | H40: 🟢 NORMAL | J40: Traslado desde DAT-04
B41: YINA MARCE YINA MARCE ZULUAGA JIMÉNEZ | C41: 1037632496 | D41: 4 | E41: 3 | F41: 1 | G41: 0.1 | H41: 🟢 NORMAL
B42: YOHIDE MARYORY PIEDRAHITA | C42: 32351188 | D42: 4 | E42: 3 | F42: 1 | G42: 0.1 | H42: 🟢 NORMAL | J42: Traslado desde DAT-04
B43: ALBANY ROJAS LÓPEZ | C43: 44001943 | D43: 4 | E43: 4 | F43: 0 | G43: 0.133 | H43: 🟢 NORMAL
...

Sheet FICHA ESTUDIANTE
B1: FICHA DEL ESTUDIANTE
B2: Escriba parte del nombre o cédula en BUSCAR. Se muestra la primera coincidencia; para elegir otra, copie su cédula de la lista de coincidencias a CÉDULA.
B4: Buscar (nombre o cédula) | C4: YOHIDE MARYORY PIEDRAHITA | E4: =IFERROR(COUNTA(INDEX(_xlfn.ANCHORARRAY($L$6),0,1))&" coincidencia(s)","") -> 1 coincidencia(s) | L4: COINCIDENCIAS DE BÚSQUEDA | P4: Datos del gráfico (automático)
B5: Cédula (opcional) | L5: Cédula | M5: Nombre | P5: Fecha | Q5: % acumulado
B6: Cédula mostrada | C6: =IF(TRIM($C$5&"")<>"",TRIM($C$5&""),IFERROR(IF(ISNUMBER(MATCH(INDEX(_xlfn.ANCHORARRAY($L$6),1,1),tblMatriculas[Cédula],0)),INDEX(_xlfn.ANCHORARRAY($L$6),1,1),""),"")) -> 32351188 | L6: {=IF($C$4="","Escriba un texto para buscar",_xlfn.LET(_xlpm.n,tblMatriculas[Nombre],_xlpm.cd,tblMatriculas[Cédula],_xlpm.k,ISNUMBER(SEARCH(TRIM($C$4),_xlpm.n))+ISNUMBER(SEARCH(TRIM($C$4),_xlpm.cd)),_xlfn.UNIQUE(_xlfn._xlws.FILTER(_xlfn.HSTACK(_xlpm.cd,_xlpm.n),_xlpm.k,"Sin coincidencias"))))} -> 32351188 | M6: YOHIDE MARYORY PIEDRAHITA | P6: {=_xlfn.LET(_xlpm.d,_xlfn._xlws.SORT(_xlfn.UNIQUE(_xlfn._xlws.FILTER(tblAsistenciaDiaria[Fecha],(tblAsistenciaDiaria[Cédula]=$C$6)*(tblAsistenciaDiaria[Fecha]<>""),""))),_xlpm.i,ROW()-5,IFERROR(IF(INDEX(_xlpm.d,_xlpm.i)="",NA(),INDEX(_xlpm.d,_xlpm.i)),NA()))} -> #N/A | Q6: {=IFERROR(_xlfn.LET(_xlpm.t,COUNTIFS(tblAsistenciaDiaria[Cédula],$C$6,tblAsistenciaDiaria[Fecha],"<="&P6),SUM(COUNTIFS(tblAsistenciaDiaria[Cédula],$C$6,tblAsistenciaDiaria[Fecha],"<="&P6,tblAsistenciaDiaria[Estado],{"Presente","Tarde"}))/_xlpm.t),NA())} -> #N/A
P7: {=_xlfn.LET(_xlpm.d,_xlfn._xlws.SORT(_xlfn.UNIQUE(_xlfn._xlws.FILTER(tblAsistenciaDiaria[Fecha],(tblAsistenciaDiaria[Cédula]=$C$6)*(tblAsistenciaDiaria[Fecha]<>""),""))),_xlpm.i,ROW()-5,IFERROR(IF(INDEX(_xlpm.d,_xlpm.i)="",NA(),INDEX(_xlpm.d,_xlpm.i)),NA()))} -> #N/A | Q7: {=IFERROR(_xlfn.LET(_xlpm.t,COUNTIFS(tblAsistenciaDiaria[Cédula],$C$6,tblAsistenciaDiaria[Fecha],"<="&P7),SUM(COUNTIFS(tblAsistenciaDiaria[Cédula],$C$6,tblAsistenciaDiaria[Fecha],"<="&P7,tblAsistenciaDiaria[Estado],{"Presente","Tarde"}))/_xlpm.t),NA())} -> #N/A
B8: INFORMACIÓN | G8: INDICADORES (grupos activos) | P8: {=_xlfn.LET(_xlpm.d,_xlfn._xlws.SORT(_xlfn.UNIQUE(_xlfn._xlws.FILTER(tblAsistenciaDiaria[Fecha],(tblAsistenciaDiaria[Cédula]=$C$6)*(tblAsistenciaDiaria[Fecha]<>""),""))),_xlpm.i,ROW()-5,IFERROR(IF(INDEX(_xlpm.d,_xlpm.i)="",NA(),INDEX(_xlpm.d,_xlpm.i)),NA()))} -> #N/A | Q8: {=IFERROR(_xlfn.LET(_xlpm.t,COUNTIFS(tblAsistenciaDiaria[Cédula],$C$6,tblAsistenciaDiaria[Fecha],"<="&P8),SUM(COUNTIFS(tblAsistenciaDiaria[Cédula],$C$6,tblAsistenciaDiaria[Fecha],"<="&P8,tblAsistenciaDiaria[Estado],{"Presente","Tarde"}))/_xlpm.t),NA())} -> #N/A
B9: Nombre | C9: =IFERROR(_xlfn.XLOOKUP($C$6,tblMatriculas[Cédula],tblMatriculas[Nombre]),"—") -> YOHIDE MARYORY PIEDRAHITA | G9: Total clases dictadas | H9: =SUMIFS(tblMatriculas[Clases dictadas],tblMatriculas[Cédula],$C$6,tblMatriculas[Incluir],TRUE) -> 4 | P9: {=_xlfn.LET(_xlpm.d,_xlfn._xlws.SORT(_xlfn.UNIQUE(_xlfn._xlws.FILTER(tblAsistenciaDiaria[Fecha],(tblAsistenciaDiaria[Cédula]=$C$6)*(tblAsistenciaDiaria[Fecha]<>""),""))),_xlpm.i,ROW()-5,IFERROR(IF(INDEX(_xlpm.d,_xlpm.i)="",NA(),INDEX(_xlpm.d,_xlpm.i)),NA()))} -> #N/A | Q9: {=IFERROR(_xlfn.LET(_xlpm.t,COUNTIFS(tblAsistenciaDiaria[Cédula],$C$6,tblAsistenciaDiaria[Fecha],"<="&P9),SUM(COUNTIFS(tblAsistenciaDiaria[Cédula],$C$6,tblAsistenciaDiaria[Fecha],"<="&P9,tblAsistenciaDiaria[Estado],{"Presente","Tarde"}))/_xlpm.t),NA())} -> #N/A
B10: Identificación | C10: =IF($C$6="","—",$C$6) -> 32351188 | G10: Asistencias | H10: =SUMIFS(tblMatriculas[Asistidas],tblMatriculas[Cédula],$C$6,tblMatriculas[Incluir],TRUE) -> 3 | P10: {=_xlfn.LET(_xlpm.d,_xlfn._xlws.SORT(_xlfn.UNIQUE(_xlfn._xlws.FILTER(tblAsistenciaDiaria[Fecha],(tblAsistenciaDiaria[Cédula]=$C$6)*(tblAsistenciaDiaria[Fecha]<>""),""))),_xlpm.i,ROW()-5,IFERROR(IF(INDEX(_xlpm.d,_xlpm.i)="",NA(),INDEX(_xlpm.d,_xlpm.i)),NA()))} -> #N/A | Q10: {=IFERROR(_xlfn.LET(_xlpm.t,COUNTIFS(tblAsistenciaDiaria[Cédula],$C$6,tblAsistenciaDiaria[Fecha],"<="&P10),SUM(COUNTIFS(tblAsistenciaDiaria[Cédula],$C$6,tblAsistenciaDiaria[Fecha],"<="&P10,tblAsistenciaDiaria[Estado],{"Presente","Tarde"}))/_xlpm.t),NA())} -> #N/A
B11: Grupo(s) activo(s) | C11: {=IFERROR(_xlfn.TEXTJOIN(", ",TRUE,_xlfn._xlws.FILTER(tblMatriculas[Código],(tblMatriculas[Cédula]=$C$6)*(tblMatriculas[Estado]="activa"))),"Ninguno")} -> DAT-02 | G11: Inasistencias | H11: =SUMIFS(tblMatriculas[Inasistencias],tblMatriculas[Cédula],$C$6,tblMatriculas[Incluir],TRUE) -> 1 | P11: {=_xlfn.LET(_xlpm.d,_xlfn._xlws.SORT(_xlfn.UNIQUE(_xlfn._xlws.FILTER(tblAsistenciaDiaria[Fecha],(tblAsistenciaDiaria[Cédula]=$C$6)*(tblAsistenciaDiaria[Fecha]<>""),""))),_xlpm.i,ROW()-5,IFERROR(IF(INDEX(_xlpm.d,_xlpm.i)="",NA(),INDEX(_xlpm.d,_xlpm.i)),NA()))} -> #N/A | Q11: {=IFERROR(_xlfn.LET(_xlpm.t,COUNTIFS(tblAsistenciaDiaria[Cédula],$C$6,tblAsistenciaDiaria[Fecha],"<="&P11),SUM(COUNTIFS(tblAsistenciaDiaria[Cédula],$C$6,tblAsistenciaDiaria[Fecha],"<="&P11,tblAsistenciaDiaria[Estado],{"Presente","Tarde"}))/_xlpm.t),NA())} -> #N/A
B12: Curso(s) / programa(s) | C12: {=IFERROR(_xlfn.TEXTJOIN(" | ",TRUE,_xlfn.UNIQUE(_xlfn._xlws.FILTER(tblMatriculas[Programa],(tblMatriculas[Cédula]=$C$6)*(tblMatriculas[Estado]="activa")))),"—")} -> ANÁLISIS Y VISUALIZACIÓN DE DATOS PARA LA TOMA DE DECISIONES | G12: % asistencia | H12: =IFERROR(AVERAGEIFS(tblMatriculas[% asistencia],tblMatriculas[Cédula],$C$6,tblMatriculas[Incluir],TRUE),"") -> 0.1 | P12: {=_xlfn.LET(_xlpm.d,_xlfn._xlws.SORT(_xlfn.UNIQUE(_xlfn._xlws.FILTER(tblAsistenciaDiaria[Fecha],(tblAsistenciaDiaria[Cédula]=$C$6)*(tblAsistenciaDiaria[Fecha]<>""),""))),_xlpm.i,ROW()-5,IFERROR(IF(INDEX(_xlpm.d,_xlpm.i)="",NA(),INDEX(_xlpm.d,_xlpm.i)),NA()))} -> #N/A | Q12: {=IFERROR(_xlfn.LET(_xlpm.t,COUNTIFS(tblAsistenciaDiaria[Cédula],$C$6,tblAsistenciaDiaria[Fecha],"<="&P12),SUM(COUNTIFS(tblAsistenciaDiaria[Cédula],$C$6,tblAsistenciaDiaria[Fecha],"<="&P12,tblAsistenciaDiaria[Estado],{"Presente","Tarde"}))/_xlpm.t),NA())} -> #N/A
B13: Docente(s) | C13: {=IFERROR(_xlfn.TEXTJOIN(", ",TRUE,_xlfn.UNIQUE(_xlfn._xlws.FILTER(tblMatriculas[Docente],(tblMatriculas[Cédula]=$C$6)*(tblMatriculas[Estado]="activa")))),"—")} -> César Diaz | G13: Faltas consecutivas | H13: =IF(COUNTA(tblAsistenciaDiaria[Fecha])=0,"Requiere DATOS",_xlfn.MAXIFS(tblMatriculas[Faltas consecutivas],tblMatriculas[Cédula],$C$6)) -> Requiere DATOS | P13: {=_xlfn.LET(_xlpm.d,_xlfn._xlws.SORT(_xlfn.UNIQUE(_xlfn._xlws.FILTER(tblAsistenciaDiaria[Fecha],(tblAsistenciaDiaria[Cédula]=$C$6)*(tblAsistenciaDiaria[Fecha]<>""),""))),_xlpm.i,ROW()-5,IFERROR(IF(INDEX(_xlpm.d,_xlpm.i)="",NA(),INDEX(_xlpm.d,_xlpm.i)),NA()))} -> #N/A | Q13: {=IFERROR(_xlfn.LET(_xlpm.t,COUNTIFS(tblAsistenciaDiaria[Cédula],$C$6,tblAsistenciaDiaria[Fecha],"<="&P13),SUM(COUNTIFS(tblAsistenciaDiaria[Cédula],$C$6,tblAsistenciaDiaria[Fecha],"<="&P13,tblAsistenciaDiaria[Estado],{"Presente","Tarde"}))/_xlpm.t),NA())} -> #N/A
B14: Correo (Base Estudiantes) | C14: =IFERROR(_xlfn.XLOOKUP($C$6,'Base Estudiantes'!$C:$C,'Base Estudiantes'!$E:$E),"No está en Base Estudiantes") -> maryorypiedrahita@hotmail.com | G14: Última asistencia registrada | H14: =IF(COUNTA(tblAsistenciaDiaria[Fecha])=0,"Requiere DATOS",_xlfn.LET(_xlpm.m,_xlfn.MAXIFS(tblAsistenciaDiaria[Fecha],tblAsistenciaDiaria[Cédula],$C$6,tblAsistenciaDiaria[Estado],"Presente"),IF(_xlpm.m=0,"Sin registro",_xlpm.m))) -> Requiere DATOS | P14: {=_xlfn.LET(_xlpm.d,_xlfn._xlws.SORT(_xlfn.UNIQUE(_xlfn._xlws.FILTER(tblAsistenciaDiaria[Fecha],(tblAsistenciaDiaria[Cédula]=$C$6)*(tblAsistenciaDiaria[Fecha]<>""),""))),_xlpm.i,ROW()-5,IFERROR(IF(INDEX(_xlpm.d,_xlpm.i)="",NA(),INDEX(_xlpm.d,_xlpm.i)),NA()))} -> #N/A | Q14: {=IFERROR(_xlfn.LET(_xlpm.t,COUNTIFS(tblAsistenciaDiaria[Cédula],$C$6,tblAsistenciaDiaria[Fecha],"<="&P14),SUM(COUNTIFS(tblAsistenciaDiaria[Cédula],$C$6,tblAsistenciaDiaria[Fecha],"<="&P14,tblAsistenciaDiaria[Estado],{"Presente","Tarde"}))/_xlpm.t),NA())} -> #N/A
B15: Teléfono (Base Estudiantes) | C15: =IFERROR(_xlfn.XLOOKUP($C$6,'Base Estudiantes'!$C:$C,'Base Estudiantes'!$F:$F)&"","—") -> 3117083744 | G15: Última inasistencia registrada | H15: =IF(COUNTA(tblAsistenciaDiaria[Fecha])=0,"Requiere DATOS",_xlfn.LET(_xlpm.m,_xlfn.MAXIFS(tblAsistenciaDiaria[Fecha],tblAsistenciaDiaria[Cédula],$C$6,tblAsistenciaDiaria[Estado],"Ausente"),IF(_xlpm.m=0,"Sin registro",_xlpm.m))) -> Requiere DATOS | P15: {=_xlfn.LET(_xlpm.d,_xlfn._xlws.SORT(_xlfn.UNIQUE(_xlfn._xlws.FILTER(tblAsistenciaDiaria[Fecha],(tblAsistenciaDiaria[Cédula]=$C$6)*(tblAsistenciaDiaria[Fecha]<>""),""))),_xlpm.i,ROW()-5,IFERROR(IF(INDEX(_xlpm.d,_xlpm.i)="",NA(),INDEX(_xlpm.d,_xlpm.i)),NA()))} -> #N/A | Q15: {=IFERROR(_xlfn.LET(_xlpm.t,COUNTIFS(tblAsistenciaDiaria[Cédula],$C$6,tblAsistenciaDiaria[Fecha],"<="&P15),SUM(COUNTIFS(tblAsistenciaDiaria[Cédula],$C$6,tblAsistenciaDiaria[Fecha],"<="&P15,tblAsistenciaDiaria[Estado],{"Presente","Tarde"}))/_xlpm.t),NA())} -> #N/A
G16: Estado actual | H16: =IF($C$6="","—",IF(H12="",IF(COUNTIFS(tblMatriculas[Cédula],$C$6,tblMatriculas[Estado],"activa")=0,"Retirado","⚪ SIN REGISTRO"),XLOOKUP(ROUND(H12,3),tblNiveles[Hasta (% asistencia, incluido)],tblNiveles[Nivel],,1))) | P16: {=_xlfn.LET(_xlpm.d,_xlfn._xlws.SORT(_xlfn.UNIQUE(_xlfn._xlws.FILTER(tblAsistenciaDiaria[Fecha],(tblAsistenciaDiaria[Cédula]=$C$6)*(tblAsistenciaDiaria[Fecha]<>""),""))),_xlpm.i,ROW()-5,IFERROR(IF(INDEX(_xlpm.d,_xlpm.i)="",NA(),INDEX(_xlpm.d,_xlpm.i)),NA()))} -> #N/A | Q16: {=IFERROR(_xlfn.LET(_xlpm.t,COUNTIFS(tblAsistenciaDiaria[Cédula],$C$6,tblAsistenciaDiaria[Fecha],"<="&P16),SUM(COUNTIFS(tblAsistenciaDiaria[Cédula],$C$6,tblAsistenciaDiaria[Fecha],"<="&P16,tblAsistenciaDiaria[Estado],{"Presente","Tarde"}))/_xlpm.t),NA())} -> #N/A
G17: Alertas activas | H17: {=IFERROR(_xlfn.TEXTJOIN(" | ",TRUE,_xlfn.UNIQUE(_xlfn._xlws.FILTER(tblMatriculas[Tipo de alerta],(tblMatriculas[Cédula]=$C$6)*(tblMatriculas[Tipo de alerta]<>"")))),"Ninguna")} -> Ninguna | P17: {=_xlfn.LET(_xlpm.d,_xlfn._xlws.SORT(_xlfn.UNIQUE(_xlfn._xlws.FILTER(tblAsistenciaDiaria[Fecha],(tblAsistenciaDiaria[Cédula]=$C$6)*(tblAsistenciaDiaria[Fecha]<>""),""))),_xlpm.i,ROW()-5,IFERROR(IF(INDEX(_xlpm.d,_xlpm.i)="",NA(),INDEX(_xlpm.d,_xlpm.i)),NA()))} -> #N/A | Q17: {=IFERROR(_xlfn.LET(_xlpm.t,COUNTIFS(tblAsistenciaDiaria[Cédula],$C$6,tblAsistenciaDiaria[Fecha],"<="&P17),SUM(COUNTIFS(tblAsistenciaDiaria[Cédula],$C$6,tblAsistenciaDiaria[Fecha],"<="&P17,tblAsistenciaDiaria[Estado],{"Presente","Tarde"}))/_xlpm.t),NA())} -> #N/A
P18: {=_xlfn.LET(_xlpm.d,_xlfn._xlws.SORT(_xlfn.UNIQUE(_xlfn._xlws.FILTER(tblAsistenciaDiaria[Fecha],(tblAsistenciaDiaria[Cédula]=$C$6)*(tblAsistenciaDiaria[Fecha]<>""),""))),_xlpm.i,ROW()-5,IFERROR(IF(INDEX(_xlpm.d,_xlpm.i)="",NA(),INDEX(_xlpm.d,_xlpm.i)),NA()))} -> #N/A | Q18: {=IFERROR(_xlfn.LET(_xlpm.t,COUNTIFS(tblAsistenciaDiaria[Cédula],$C$6,tblAsistenciaDiaria[Fecha],"<="&P18),SUM(COUNTIFS(tblAsistenciaDiaria[Cédula],$C$6,tblAsistenciaDiaria[Fecha],"<="&P18,tblAsistenciaDiaria[Estado],{"Presente","Tarde"}))/_xlpm.t),NA())} -> #N/A
B19: MATRÍCULAS DEL ESTUDIANTE (todas, incluye retiros y traslados) | P19: {=_xlfn.LET(_xlpm.d,_xlfn._xlws.SORT(_xlfn.UNIQUE(_xlfn._xlws.FILTER(tblAsistenciaDiaria[Fecha],(tblAsistenciaDiaria[Cédula]=$C$6)*(tblAsistenciaDiaria[Fecha]<>""),""))),_xlpm.i,ROW()-5,IFERROR(IF(INDEX(_xlpm.d,_xlpm.i)="",NA(),INDEX(_xlpm.d,_xlpm.i)),NA()))} -> #N/A | Q19: {=IFERROR(_xlfn.LET(_xlpm.t,COUNTIFS(tblAsistenciaDiaria[Cédula],$C$6,tblAsistenciaDiaria[Fecha],"<="&P19),SUM(COUNTIFS(tblAsistenciaDiaria[Cédula],$C$6,tblAsistenciaDiaria[Fecha],"<="&P19,tblAsistenciaDiaria[Estado],{"Presente","Tarde"}))/_xlpm.t),NA())} -> #N/A
B20: Grupo | C20: Estado matrícula | D20: Asistencias | E20: Clases dictadas | F20: Inasistencias | G20: % Asistencia | H20: Nivel | I20: Tipo de alerta | J20: Observación | P20: {=_xlfn.LET(_xlpm.d,_xlfn._xlws.SORT(_xlfn.UNIQUE(_xlfn._xlws.FILTER(tblAsistenciaDiaria[Fecha],(tblAsistenciaDiaria[Cédula]=$C$6)*(tblAsistenciaDiaria[Fecha]<>""),""))),_xlpm.i,ROW()-5,IFERROR(IF(INDEX(_xlpm.d,_xlpm.i)="",NA(),INDEX(_xlpm.d,_xlpm.i)),NA()))} -> #N/A | Q20: {=IFERROR(_xlfn.LET(_xlpm.t,COUNTIFS(tblAsistenciaDiaria[Cédula],$C$6,tblAsistenciaDiaria[Fecha],"<="&P20),SUM(COUNTIFS(tblAsistenciaDiaria[Cédula],$C$6,tblAsistenciaDiaria[Fecha],"<="&P20,tblAsistenciaDiaria[Estado],{"Presente","Tarde"}))/_xlpm.t),NA())} -> #N/A
B21: {=IF($C$6="","",_xlfn._xlws.FILTER(_xlfn.HSTACK(tblMatriculas[Grupo],tblMatriculas[Estado],tblMatriculas[Asistidas],tblMatriculas[Clases dictadas],tblMatriculas[Inasistencias],tblMatriculas[% asistencia],tblMatriculas[Nivel],tblMatriculas[Tipo de alerta],tblMatriculas[Observación]),tblMatriculas[Cédula]=$C$6,"Sin matrículas"))} -> DAT-02 - Análisis y Visualización de Datos | C21: activa | D21: 3 | E21: 4 | F21: 1 | G21: 0.1 | H21: 🟢 NORMAL | J21: Traslado desde DAT-04 | P21: {=_xlfn.LET(_xlpm.d,_xlfn._xlws.SORT(_xlfn.UNIQUE(_xlfn._xlws.FILTER(tblAsistenciaDiaria[Fecha],(tblAsistenciaDiaria[Cédula]=$C$6)*(tblAsistenciaDiaria[Fecha]<>""),""))),_xlpm.i,ROW()-5,IFERROR(IF(INDEX(_xlpm.d,_xlpm.i)="",NA(),INDEX(_xlpm.d,_xlpm.i)),NA()))} -> #N/A | Q21: {=IFERROR(_xlfn.LET(_xlpm.t,COUNTIFS(tblAsistenciaDiaria[Cédula],$C$6,tblAsistenciaDiaria[Fecha],"<="&P21),SUM(COUNTIFS(tblAsistenciaDiaria[Cédula],$C$6,tblAsistenciaDiaria[Fecha],"<="&P21,tblAsistenciaDiaria[Estado],{"Presente","Tarde"}))/_xlpm.t),NA())} -> #N/A
P22: {=_xlfn.LET(_xlpm.d,_xlfn._xlws.SORT(_xlfn.UNIQUE(_xlfn._xlws.FILTER(tblAsistenciaDiaria[Fecha],(tblAsistenciaDiaria[Cédula]=$C$6)*(tblAsistenciaDiaria[Fecha]<>""),""))),_xlpm.i,ROW()-5,IFERROR(IF(INDEX(_xlpm.d,_xlpm.i)="",NA(),INDEX(_xlpm.d,_xlpm.i)),NA()))} -> #N/A | Q22: {=IFERROR(_xlfn.LET(_xlpm.t,COUNTIFS(tblAsistenciaDiaria[Cédula],$C$6,tblAsistenciaDiaria[Fecha],"<="&P22),SUM(COUNTIFS(tblAsistenciaDiaria[Cédula],$C$6,tblAsistenciaDiaria[Fecha],"<="&P22,tblAsistenciaDiaria[Estado],{"Presente","Tarde"}))/_xlpm.t),NA())} -> #N/A
P23: {=_xlfn.LET(_xlpm.d,_xlfn._xlws.SORT(_xlfn.UNIQUE(_xlfn._xlws.FILTER(tblAsistenciaDiaria[Fecha],(tblAsistenciaDiaria[Cédula]=$C$6)*(tblAsistenciaDiaria[Fecha]<>""),""))),_xlpm.i,ROW()-5,IFERROR(IF(INDEX(_xlpm.d,_xlpm.i)="",NA(),INDEX(_xlpm.d,_xlpm.i)),NA()))} -> #N/A | Q23: {=IFERROR(_xlfn.LET(_xlpm.t,COUNTIFS(tblAsistenciaDiaria[Cédula],$C$6,tblAsistenciaDiaria[Fecha],"<="&P23),SUM(COUNTIFS(tblAsistenciaDiaria[Cédula],$C$6,tblAsistenciaDiaria[Fecha],"<="&P23,tblAsistenciaDiaria[Estado],{"Presente","Tarde"}))/_xlpm.t),NA())} -> #N/A
P24: {=_xlfn.LET(_xlpm.d,_xlfn._xlws.SORT(_xlfn.UNIQUE(_xlfn._xlws.FILTER(tblAsistenciaDiaria[Fecha],(tblAsistenciaDiaria[Cédula]=$C$6)*(tblAsistenciaDiaria[Fecha]<>""),""))),_xlpm.i,ROW()-5,IFERROR(IF(INDEX(_xlpm.d,_xlpm.i)="",NA(),INDEX(_xlpm.d,_xlpm.i)),NA()))} -> #N/A | Q24: {=IFERROR(_xlfn.LET(_xlpm.t,COUNTIFS(tblAsistenciaDiaria[Cédula],$C$6,tblAsistenciaDiaria[Fecha],"<="&P24),SUM(COUNTIFS(tblAsistenciaDiaria[Cédula],$C$6,tblAsistenciaDiaria[Fecha],"<="&P24,tblAsistenciaDiaria[Estado],{"Presente","Tarde"}))/_xlpm.t),NA())} -> #N/A
P25: {=_xlfn.LET(_xlpm.d,_xlfn._xlws.SORT(_xlfn.UNIQUE(_xlfn._xlws.FILTER(tblAsistenciaDiaria[Fecha],(tblAsistenciaDiaria[Cédula]=$C$6)*(tblAsistenciaDiaria[Fecha]<>""),""))),_xlpm.i,ROW()-5,IFERROR(IF(INDEX(_xlpm.d,_xlpm.i)="",NA(),INDEX(_xlpm.d,_xlpm.i)),NA()))} -> #N/A | Q25: {=IFERROR(_xlfn.LET(_xlpm.t,COUNTIFS(tblAsistenciaDiaria[Cédula],$C$6,tblAsistenciaDiaria[Fecha],"<="&P25),SUM(COUNTIFS(tblAsistenciaDiaria[Cédula],$C$6,tblAsistenciaDiaria[Fecha],"<="&P25,tblAsistenciaDiaria[Estado],{"Presente","Tarde"}))/_xlpm.t),NA())} -> #N/A
P26: {=_xlfn.LET(_xlpm.d,_xlfn._xlws.SORT(_xlfn.UNIQUE(_xlfn._xlws.FILTER(tblAsistenciaDiaria[Fecha],(tblAsistenciaDiaria[Cédula]=$C$6)*(tblAsistenciaDiaria[Fecha]<>""),""))),_xlpm.i,ROW()-5,IFERROR(IF(INDEX(_xlpm.d,_xlpm.i)="",NA(),INDEX(_xlpm.d,_xlpm.i)),NA()))} -> #N/A | Q26: {=IFERROR(_xlfn.LET(_xlpm.t,COUNTIFS(tblAsistenciaDiaria[Cédula],$C$6,tblAsistenciaDiaria[Fecha],"<="&P26),SUM(COUNTIFS(tblAsistenciaDiaria[Cédula],$C$6,tblAsistenciaDiaria[Fecha],"<="&P26,tblAsistenciaDiaria[Estado],{"Presente","Tarde"}))/_xlpm.t),NA())} -> #N/A
P27: {=_xlfn.LET(_xlpm.d,_xlfn._xlws.SORT(_xlfn.UNIQUE(_xlfn._xlws.FILTER(tblAsistenciaDiaria[Fecha],(tblAsistenciaDiaria[Cédula]=$C$6)*(tblAsistenciaDiaria[Fecha]<>""),""))),_xlpm.i,ROW()-5,IFERROR(IF(INDEX(_xlpm.d,_xlpm.i)="",NA(),INDEX(_xlpm.d,_xlpm.i)),NA()))} -> #N/A | Q27: {=IFERROR(_xlfn.LET(_xlpm.t,COUNTIFS(tblAsistenciaDiaria[Cédula],$C$6,tblAsistenciaDiaria[Fecha],"<="&P27),SUM(COUNTIFS(tblAsistenciaDiaria[Cédula],$C$6,tblAsistenciaDiaria[Fecha],"<="&P27,tblAsistenciaDiaria[Estado],{"Presente","Tarde"}))/_xlpm.t),NA())} -> #N/A
P28: {=_xlfn.LET(_xlpm.d,_xlfn._xlws.SORT(_xlfn.UNIQUE(_xlfn._xlws.FILTER(tblAsistenciaDiaria[Fecha],(tblAsistenciaDiaria[Cédula]=$C$6)*(tblAsistenciaDiaria[Fecha]<>""),""))),_xlpm.i,ROW()-5,IFERROR(IF(INDEX(_xlpm.d,_xlpm.i)="",NA(),INDEX(_xlpm.d,_xlpm.i)),NA()))} -> #N/A | Q28: {=IFERROR(_xlfn.LET(_xlpm.t,COUNTIFS(tblAsistenciaDiaria[Cédula],$C$6,tblAsistenciaDiaria[Fecha],"<="&P28),SUM(COUNTIFS(tblAsistenciaDiaria[Cédula],$C$6,tblAsistenciaDiaria[Fecha],"<="&P28,tblAsistenciaDiaria[Estado],{"Presente","Tarde"}))/_xlpm.t),NA())} -> #N/A
P29: {=_xlfn.LET(_xlpm.d,_xlfn._xlws.SORT(_xlfn.UNIQUE(_xlfn._xlws.FILTER(tblAsistenciaDiaria[Fecha],(tblAsistenciaDiaria[Cédula]=$C$6)*(tblAsistenciaDiaria[Fecha]<>""),""))),_xlpm.i,ROW()-5,IFERROR(IF(INDEX(_xlpm.d,_xlpm.i)="",NA(),INDEX(_xlpm.d,_xlpm.i)),NA()))} -> #N/A | Q29: {=IFERROR(_xlfn.LET(_xlpm.t,COUNTIFS(tblAsistenciaDiaria[Cédula],$C$6,tblAsistenciaDiaria[Fecha],"<="&P29),SUM(COUNTIFS(tblAsistenciaDiaria[Cédula],$C$6,tblAsistenciaDiaria[Fecha],"<="&P29,tblAsistenciaDiaria[Estado],{"Presente","Tarde"}))/_xlpm.t),NA())} -> #N/A
P30: {=_xlfn.LET(_xlpm.d,_xlfn._xlws.SORT(_xlfn.UNIQUE(_xlfn._xlws.FILTER(tblAsistenciaDiaria[Fecha],(tblAsistenciaDiaria[Cédula]=$C$6)*(tblAsistenciaDiaria[Fecha]<>""),""))),_xlpm.i,ROW()-5,IFERROR(IF(INDEX(_xlpm.d,_xlpm.i)="",NA(),INDEX(_xlpm.d,_xlpm.i)),NA()))} -> #N/A | Q30: {=IFERROR(_xlfn.LET(_xlpm.t,COUNTIFS(tblAsistenciaDiaria[Cédula],$C$6,tblAsistenciaDiaria[Fecha],"<="&P30),SUM(COUNTIFS(tblAsistenciaDiaria[Cédula],$C$6,tblAsistenciaDiaria[Fecha],"<="&P30,tblAsistenciaDiaria[Estado],{"Presente","Tarde"}))/_xlpm.t),NA())} -> #N/A
P31: {=_xlfn.LET(_xlpm.d,_xlfn._xlws.SORT(_xlfn.UNIQUE(_xlfn._xlws.FILTER(tblAsistenciaDiaria[Fecha],(tblAsistenciaDiaria[Cédula]=$C$6)*(tblAsistenciaDiaria[Fecha]<>""),""))),_xlpm.i,ROW()-5,IFERROR(IF(INDEX(_xlpm.d,_xlpm.i)="",NA(),INDEX(_xlpm.d,_xlpm.i)),NA()))} -> #N/A | Q31: {=IFERROR(_xlfn.LET(_xlpm.t,COUNTIFS(tblAsistenciaDiaria[Cédula],$C$6,tblAsistenciaDiaria[Fecha],"<="&P31),SUM(COUNTIFS(tblAsistenciaDiaria[Cédula],$C$6,tblAsistenciaDiaria[Fecha],"<="&P31,tblAsistenciaDiaria[Estado],{"Presente","Tarde"}))/_xlpm.t),NA())} -> #N/A
B32: HISTORIAL DE ASISTENCIA (desde hoja DATOS) | P32: {=_xlfn.LET(_xlpm.d,_xlfn._xlws.SORT(_xlfn.UNIQUE(_xlfn._xlws.FILTER(tblAsistenciaDiaria[Fecha],(tblAsistenciaDiaria[Cédula]=$C$6)*(tblAsistenciaDiaria[Fecha]<>""),""))),_xlpm.i,ROW()-5,IFERROR(IF(INDEX(_xlpm.d,_xlpm.i)="",NA(),INDEX(_xlpm.d,_xlpm.i)),NA()))} -> #N/A | Q32: {=IFERROR(_xlfn.LET(_xlpm.t,COUNTIFS(tblAsistenciaDiaria[Cédula],$C$6,tblAsistenciaDiaria[Fecha],"<="&P32),SUM(COUNTIFS(tblAsistenciaDiaria[Cédula],$C$6,tblAsistenciaDiaria[Fecha],"<="&P32,tblAsistenciaDiaria[Estado],{"Presente","Tarde"}))/_xlpm.t),NA())} -> #N/A
B33: Fecha | C33: Curso / grupo | D33: Estado | P33: {=_xlfn.LET(_xlpm.d,_xlfn._xlws.SORT(_xlfn.UNIQUE(_xlfn._xlws.FILTER(tblAsistenciaDiaria[Fecha],(tblAsistenciaDiaria[Cédula]=$C$6)*(tblAsistenciaDiaria[Fecha]<>""),""))),_xlpm.i,ROW()-5,IFERROR(IF(INDEX(_xlpm.d,_xlpm.i)="",NA(),INDEX(_xlpm.d,_xlpm.i)),NA()))} -> #N/A | Q33: {=IFERROR(_xlfn.LET(_xlpm.t,COUNTIFS(tblAsistenciaDiaria[Cédula],$C$6,tblAsistenciaDiaria[Fecha],"<="&P33),SUM(COUNTIFS(tblAsistenciaDiaria[Cédula],$C$6,tblAsistenciaDiaria[Fecha],"<="&P33,tblAsistenciaDiaria[Estado],{"Presente","Tarde"}))/_xlpm.t),NA())} -> #N/A
B34: {=IF($C$6="","",IFERROR(_xlfn._xlws.SORT(_xlfn._xlws.FILTER(_xlfn.HSTACK(tblAsistenciaDiaria[Fecha],tblAsistenciaDiaria[Código grupo],tblAsistenciaDiaria[Estado]),tblAsistenciaDiaria[Cédula]=$C$6),1,-1),"Sin registros diarios: el archivo original no tiene fechas. Cargue la hoja DATOS."))} -> Sin registros diarios: el archivo original no tiene fechas. Cargue la hoja DATOS. | P34: {=_xlfn.LET(_xlpm.d,_xlfn._xlws.SORT(_xlfn.UNIQUE(_xlfn._xlws.FILTER(tblAsistenciaDiaria[Fecha],(tblAsistenciaDiaria[Cédula]=$C$6)*(tblAsistenciaDiaria[Fecha]<>""),""))),_xlpm.i,ROW()-5,IFERROR(IF(INDEX(_xlpm.d,_xlpm.i)="",NA(),INDEX(_xlpm.d,_xlpm.i)),NA()))} -> #N/A | Q34: {=IFERROR(_xlfn.LET(_xlpm.t,COUNTIFS(tblAsistenciaDiaria[Cédula],$C$6,tblAsistenciaDiaria[Fecha],"<="&P34),SUM(COUNTIFS(tblAsistenciaDiaria[Cédula],$C$6,tblAsistenciaDiaria[Fecha],"<="&P34,tblAsistenciaDiaria[Estado],{"Presente","Tarde"}))/_xlpm.t),NA())} -> #N/A
P35: {=_xlfn.LET(_xlpm.d,_xlfn._xlws.SORT(_xlfn.UNIQUE(_xlfn._xlws.FILTER(tblAsistenciaDiaria[Fecha],(tblAsistenciaDiaria[Cédula]=$C$6)*(tblAsistenciaDiaria[Fecha]<>""),""))),_xlpm.i,ROW()-5,IFERROR(IF(INDEX(_xlpm.d,_xlpm.i)="",NA(),INDEX(_xlpm.d,_xlpm.i)),NA()))} -> #N/A | Q35: {=IFERROR(_xlfn.LET(_xlpm.t,COUNTIFS(tblAsistenciaDiaria[Cédula],$C$6,tblAsistenciaDiaria[Fecha],"<="&P35),SUM(COUNTIFS(tblAsistenciaDiaria[Cédula],$C$6,tblAsistenciaDiaria[Fecha],"<="&P35,tblAsistenciaDiaria[Estado],{"Presente","Tarde"}))/_xlpm.t),NA())} -> #N/A
P36: {=_xlfn.LET(_xlpm.d,_xlfn._xlws.SORT(_xlfn.UNIQUE(_xlfn._xlws.FILTER(tblAsistenciaDiaria[Fecha],(tblAsistenciaDiaria[Cédula]=$C$6)*(tblAsistenciaDiaria[Fecha]<>""),""))),_xlpm.i,ROW()-5,IFERROR(IF(INDEX(_xlpm.d,_xlpm.i)="",NA(),INDEX(_xlpm.d,_xlpm.i)),NA()))} -> #N/A | Q36: {=IFERROR(_xlfn.LET(_xlpm.t,COUNTIFS(tblAsistenciaDiaria[Cédula],$C$6,tblAsistenciaDiaria[Fecha],"<="&P36),SUM(COUNTIFS(tblAsistenciaDiaria[Cédula],$C$6,tblAsistenciaDiaria[Fecha],"<="&P36,tblAsistenciaDiaria[Estado],{"Presente","Tarde"}))/_xlpm.t),NA())} -> #N/A
P37: {=_xlfn.LET(_xlpm.d,_xlfn._xlws.SORT(_xlfn.UNIQUE(_xlfn._xlws.FILTER(tblAsistenciaDiaria[Fecha],(tblAsistenciaDiaria[Cédula]=$C$6)*(tblAsistenciaDiaria[Fecha]<>""),""))),_xlpm.i,ROW()-5,IFERROR(IF(INDEX(_xlpm.d,_xlpm.i)="",NA(),INDEX(_xlpm.d,_xlpm.i)),NA()))} -> #N/A | Q37: {=IFERROR(_xlfn.LET(_xlpm.t,COUNTIFS(tblAsistenciaDiaria[Cédula],$C$6,tblAsistenciaDiaria[Fecha],"<="&P37),SUM(COUNTIFS(tblAsistenciaDiaria[Cédula],$C$6,tblAsistenciaDiaria[Fecha],"<="&P37,tblAsistenciaDiaria[Estado],{"Presente","Tarde"}))/_xlpm.t),NA())} -> #N/A
P38: {=_xlfn.LET(_xlpm.d,_xlfn._xlws.SORT(_xlfn.UNIQUE(_xlfn._xlws.FILTER(tblAsistenciaDiaria[Fecha],(tblAsistenciaDiaria[Cédula]=$C$6)*(tblAsistenciaDiaria[Fecha]<>""),""))),_xlpm.i,ROW()-5,IFERROR(IF(INDEX(_xlpm.d,_xlpm.i)="",NA(),INDEX(_xlpm.d,_xlpm.i)),NA()))} -> #N/A | Q38: {=IFERROR(_xlfn.LET(_xlpm.t,COUNTIFS(tblAsistenciaDiaria[Cédula],$C$6,tblAsistenciaDiaria[Fecha],"<="&P38),SUM(COUNTIFS(tblAsistenciaDiaria[Cédula],$C$6,tblAsistenciaDiaria[Fecha],"<="&P38,tblAsistenciaDiaria[Estado],{"Presente","Tarde"}))/_xlpm.t),NA())} -> #N/A
P39: {=_xlfn.LET(_xlpm.d,_xlfn._xlws.SORT(_xlfn.UNIQUE(_xlfn._xlws.FILTER(tblAsistenciaDiaria[Fecha],(tblAsistenciaDiaria[Cédula]=$C$6)*(tblAsistenciaDiaria[Fecha]<>""),""))),_xlpm.i,ROW()-5,IFERROR(IF(INDEX(_xlpm.d,_xlpm.i)="",NA(),INDEX(_xlpm.d,_xlpm.i)),NA()))} -> #N/A | Q39: {=IFERROR(_xlfn.LET(_xlpm.t,COUNTIFS(tblAsistenciaDiaria[Cédula],$C$6,tblAsistenciaDiaria[Fecha],"<="&P39),SUM(COUNTIFS(tblAsistenciaDiaria[Cédula],$C$6,tblAsistenciaDiaria[Fecha],"<="&P39,tblAsistenciaDiaria[Estado],{"Presente","Tarde"}))/_xlpm.t),NA())} -> #N/A
P40: {=_xlfn.LET(_xlpm.d,_xlfn._xlws.SORT(_xlfn.UNIQUE(_xlfn._xlws.FILTER(tblAsistenciaDiaria[Fecha],(tblAsistenciaDiaria[Cédula]=$C$6)*(tblAsistenciaDiaria[Fecha]<>""),""))),_xlpm.i,ROW()-5,IFERROR(IF(INDEX(_xlpm.d,_xlpm.i)="",NA(),INDEX(_xlpm.d,_xlpm.i)),NA()))} -> #N/A | Q40: {=IFERROR(_xlfn.LET(_xlpm.t,COUNTIFS(tblAsistenciaDiaria[Cédula],$C$6,tblAsistenciaDiaria[Fecha],"<="&P40),SUM(COUNTIFS(tblAsistenciaDiaria[Cédula],$C$6,tblAsistenciaDiaria[Fecha],"<="&P40,tblAsistenciaDiaria[Estado],{"Presente","Tarde"}))/_xlpm.t),NA())} -> #N/A
P41: {=_xlfn.LET(_xlpm.d,_xlfn._xlws.SORT(_xlfn.UNIQUE(_xlfn._xlws.FILTER(tblAsistenciaDiaria[Fecha],(tblAsistenciaDiaria[Cédula]=$C$6)*(tblAsistenciaDiaria[Fecha]<>""),""))),_xlpm.i,ROW()-5,IFERROR(IF(INDEX(_xlpm.d,_xlpm.i)="",NA(),INDEX(_xlpm.d,_xlpm.i)),NA()))} -> #N/A | Q41: {=IFERROR(_xlfn.LET(_xlpm.t,COUNTIFS(tblAsistenciaDiaria[Cédula],$C$6,tblAsistenciaDiaria[Fecha],"<="&P41),SUM(COUNTIFS(tblAsistenciaDiaria[Cédula],$C$6,tblAsistenciaDiaria[Fecha],"<="&P41,tblAsistenciaDiaria[Estado],{"Presente","Tarde"}))/_xlpm.t),NA())} -> #N/A
...

Sheet ALERTAS
B1: ALERTAS — Estudiantes que requieren atención
B2: Ordenado por nivel de atención (1 = máxima). Una fila por estudiante y grupo. Excluye retirados y usuarios de prueba. Ausencias consecutivas y tendencia se activan al cargar la hoja DATOS.
B4: Programa | C4: DESARROLLO WEB Y APLICACIONES CON JAVASCRIPT FULL STACK | G4: 🔴 CRÍTICO | H4: 🟠 ALERTA | I4: 🟡 SEGUIMIENTO | J4: ⚪ SIN REGISTRO | K4: ⚠️ AUSENCIAS CONSECUTIVAS | L4: 📉 TENDENCIA NEGATIVA | M4: Estudiantes únicos con alerta
B5: Docente | C5: Brahiam Acosta | G5: =COUNTIFS(tblMatriculas[Tipo de alerta],"*"&G$4&"*",tblMatriculas[Programa],IF($C$4="(Todos)","*",$C$4),tblMatriculas[Docente],IF($C$5="(Todos)","*",$C$5)) -> 7 | H5: =COUNTIFS(tblMatriculas[Tipo de alerta],"*"&H$4&"*",tblMatriculas[Programa],IF($C$4="(Todos)","*",$C$4),tblMatriculas[Docente],IF($C$5="(Todos)","*",$C$5)) -> 9 | I5: =COUNTIFS(tblMatriculas[Tipo de alerta],"*"&I$4&"*",tblMatriculas[Programa],IF($C$4="(Todos)","*",$C$4),tblMatriculas[Docente],IF($C$5="(Todos)","*",$C$5)) -> 7 | J5: =COUNTIFS(tblMatriculas[Tipo de alerta],"*"&J$4&"*",tblMatriculas[Programa],IF($C$4="(Todos)","*",$C$4),tblMatriculas[Docente],IF($C$5="(Todos)","*",$C$5)) -> 0 | K5: =COUNTIFS(tblMatriculas[Tipo de alerta],"*"&K$4&"*",tblMatriculas[Programa],IF($C$4="(Todos)","*",$C$4),tblMatriculas[Docente],IF($C$5="(Todos)","*",$C$5)) -> 0 | L5: =COUNTIFS(tblMatriculas[Tipo de alerta],"*"&L$4&"*",tblMatriculas[Programa],IF($C$4="(Todos)","*",$C$4),tblMatriculas[Docente],IF($C$5="(Todos)","*",$C$5)) -> 0 | M5: {=IFERROR(ROWS(_xlfn.UNIQUE(_xlfn._xlws.FILTER(tblMatriculas[Cédula],(tblMatriculas[Tipo de alerta]<>"")*IF($C$4="(Todos)",1,tblMatriculas[Programa]=$C$4)*IF($C$5="(Todos)",1,tblMatriculas[Docente]=$C$5)))),0)} -> 23
B6: Tipo de alerta | C6: (Todos) | G6: matrículas (estudiante-grupo) por tipo; una matrícula puede tener varias alertas
B8: {="LISTADO DE ALERTAS — "&IFERROR(ROWS(_xlfn._xlws.FILTER(B10:B3000,B10:B3000<>"")),0)&" registros"} -> LISTADO DE ALERTAS — 23 registros
B9: Prioridad (1 = máx.) | C9: Estudiante | D9: Cédula | E9: Grupo | F9: Docente | G9: % asistencia | H9: Asistencias | I9: Faltas | J9: Faltas consecutivas | K9: Última asistencia | L9: Última inasistencia | M9: Tipo de alerta | N9: Acción sugerida
B10: {=_xlfn.LET(_xlpm.k,(tblMatriculas[Tipo de alerta]<>"")*IF($C$4="(Todos)",1,tblMatriculas[Programa]=$C$4)*IF($C$5="(Todos)",1,tblMatriculas[Docente]=$C$5)*IF($C$6="(Todos)",1,ISNUMBER(SEARCH($C$6,tblMatriculas[Tipo de alerta]))),_xlpm.d,_xlfn.HSTACK(tblMatriculas[Prioridad],tblMatriculas[Nombre],tblMatriculas[Cédula],tblMatriculas[Código],tblMatriculas[Docente],tblMatriculas[% asistencia],tblMatriculas[Asistidas],tblMatriculas[Inasistencias],tblMatriculas[Faltas consecutivas],tblMatriculas[Última asistencia],tblMatriculas[Última inasistencia],tblMatriculas[Tipo de alerta],_xlfn.XLOOKUP(tblMatriculas[Nivel],tblNiveles[Nivel],tblNiveles[Acción sugerida],"Verificar el registro de asistencia con el docente")),_xlpm.r,_xlfn._xlws.FILTER(_xlpm.d,_xlpm.k,"Sin alertas con estos filtros"),IFERROR(_xlfn.SORTBY(_xlpm.r,_xlfn.CHOOSECOLS(_xlpm.r,1),1,_xlfn.CHOOSECOLS(_xlpm.r,6),1,_xlfn.CHOOSECOLS(_xlpm.r,8),-1),_xlpm.r))} -> 1 | C10: BRAYAN ALEXIS ADRADA ZAPATA | D10: 1017255853 | E10: WEB-03 | F10: Brahiam Acosta | G10: 0 | H10: 0 | I10: 6 | M10: 🔴 CRÍTICO | N10: Contactar al estudiante esta semana y notificar a coordinación
B11: 1 | C11: DAHIANA ANDREA BUSTAMANTE JARAMILLO | D11: 1000396193 | E11: WEB-03 | F11: Brahiam Acosta | G11: 0 | H11: 0 | I11: 6 | M11: 🔴 CRÍTICO | N11: Contactar al estudiante esta semana y notificar a coordinación
B12: 1 | C12: WILLIAM JOSÉ SAAVEDRA RUEDA | D12: 71749282 | E12: WEB-03 | F12: Brahiam Acosta | G12: 0 | H12: 0 | I12: 6 | M12: 🔴 CRÍTICO | N12: Contactar al estudiante esta semana y notificar a coordinación
B13: 1 | C13: DANIEL ATEHORTUA | D13: 1152693525 | E13: WEB-03 | F13: Brahiam Acosta | G13: 0 | H13: 0 | I13: 6 | M13: 🔴 CRÍTICO | N13: Contactar al estudiante esta semana y notificar a coordinación
B14: 1 | C14: MANUEL ENRIQUE MERA MERA | D14: 1095301447 | E14: WEB-03 | F14: Brahiam Acosta | G14: 0 | H14: 0 | I14: 6 | M14: 🔴 CRÍTICO | N14: Contactar al estudiante esta semana y notificar a coordinación
B15: 1 | C15: CANDY MARCELA HENAO SALDARRIAG | D15: 1214715390 | E15: WEB-05 | F15: Brahiam Acosta | G15: 0 | H15: 0 | I15: 6 | M15: 🔴 CRÍTICO | N15: Contactar al estudiante esta semana y notificar a coordinación
B16: 1 | C16: LUISA FERNANDA VELEZ CARDENAS | D16: 1234991826 | E16: WEB-05 | F16: Brahiam Acosta | G16: 0 | H16: 0 | I16: 6 | M16: 🔴 CRÍTICO | N16: Contactar al estudiante esta semana y notificar a coordinación
B17: 2 | C17: DIEGO ALEXANDER SAENZ BOTERO | D17: 1036934179 | E17: WEB-03 | F17: Brahiam Acosta | G17: 0.033 | H17: 1 | I17: 5 | M17: 🟠 ALERTA | N17: Contactar al estudiante y acordar compromiso de asistencia
B18: 2 | C18: ADIMARO MONTOYA TORO | D18: 71268332 | E18: WEB-05 | F18: Brahiam Acosta | G18: 0.033 | H18: 1 | I18: 5 | M18: 🟠 ALERTA | N18: Contactar al estudiante y acordar compromiso de asistencia
B19: 2 | C19: ANGIE MARISELA GARCÍA RÍOS | D19: 1001132520 | E19: WEB-05 | F19: Brahiam Acosta | G19: 0.033 | H19: 1 | I19: 5 | M19: 🟠 ALERTA | N19: Contactar al estudiante y acordar compromiso de asistencia
B20: 2 | C20: CRISTIAN ALVAREZ CIRO | D20: 1152205239 | E20: WEB-05 | F20: Brahiam Acosta | G20: 0.033 | H20: 1 | I20: 5 | M20: 🟠 ALERTA | N20: Contactar al estudiante y acordar compromiso de asistencia
B21: 2 | C21: DANIEL EST DANIEL EST SANCHEZ MANCO | D21: 1000305751 | E21: WEB-02 | F21: Brahiam Acosta | G21: 0.033 | H21: 1 | I21: 4 | M21: 🟠 ALERTA | N21: Contactar al estudiante y acordar compromiso de asistencia
B22: 2 | C22: JACOB SUAREZ MUÑOZ | D22: 1033178602 | E22: WEB-02 | F22: Brahiam Acosta | G22: 0.033 | H22: 1 | I22: 4 | M22: 🟠 ALERTA | N22: Contactar al estudiante y acordar compromiso de asistencia
... B32: 3 | C32: MIGUEL ANGEL IGLESIAS MESA | D32: 1034921959 | E32: WEB-05 | F32: Brahiam Acosta | G32: 0.067 | H32: 2 | I32: 4 | M32: 🟡 SEGUIMIENTO | N32: Monitorear en las próximas clases; recordatorio al estudiante

Sheet INCONSISTENCIAS
B1: INCONSISTENCIAS DE DATOS — detección automática
B2: Ningún dato original fue modificado. Esta hoja solo señala problemas y propone cómo corregirlos en la fuente.
B4: Inconsistencia | C4: Registros | D4: Impacto | E4: Solución propuesta
B5: No hay fechas de asistencia (solo acumulados tipo 4/45) | C5: =IF(COUNT(tblAsistenciaDiaria[Fecha])=0,"Todo el archivo","Resuelto") -> Todo el archivo | D5: No se puede calcular historial, faltas consecutivas, tendencia ni evolución | E5: Exportar el registro diario de la plataforma y pegarlo en la hoja DATOS
B6: No se registran las clases dictadas por grupo | C6: =COUNTA(tblGrupos[Código])-COUNT(tblGrupos[Clases dictadas (manual)]) -> 57 | D6: El % se calcula sobre una estimación (máx. asistencias del grupo) | E6: Escribir el número real en GRUPOS, columna 'Clases dictadas (manual)'
B7: Activos sin registro de asistencia (Clases = null/null) | C7: =COUNTIFS(tblMatriculas[Nivel],"⚪ SIN REGISTRO") -> 48 | D7: No tienen % de asistencia; aparecen como ⚪ SIN REGISTRO en ALERTAS | E7: Verificar con el docente (concentrado en IAA-02 e IAA-06)
B8: Usuario de prueba en la base | C8: =COUNTIFS(tblMatriculas[Nombre],"*"&pPrueba&"*") -> 6 | D8: Distorsiona conteos si no se excluye (ya se excluye de indicadores) | E8: Eliminar de la plataforma de origen
B9: Clases acumuladas por traslado (planeadas > planeadas del grupo) | C9: {=SUMPRODUCT(--(N(+tblMatriculas[Clases planeadas])>N(+_xlfn.XLOOKUP(tblMatriculas[Código],tblGrupos[Código],tblGrupos[Clases planeadas],0))))} -> 66 | D9: Asistencias del grupo de origen se suman al de destino | E9: Ya se ajusta el denominador; idealmente separar asistencias por grupo en origen
B10: …de ellos, sin observación de traslado | C10: {=SUMPRODUCT((N(+tblMatriculas[Clases planeadas])>N(+_xlfn.XLOOKUP(tblMatriculas[Código],tblGrupos[Código],tblGrupos[Clases planeadas],0)))*(tblMatriculas[Observación]=""))} -> 28 | D10: No se sabe el grupo de origen; se estima proporcionalmente | E10: Registrar 'Traslado desde X' en la observación
B11: Asistencias mayores que clases dictadas estimadas | C11: {=SUMPRODUCT((tblMatriculas[Estado]="activa")*(N(+tblMatriculas[Asistidas])>N(+tblMatriculas[Clases dictadas])))} -> 0 | D11: % limitado a 100% | E11: Cargar clases dictadas reales en GRUPOS
B12: Matrículas activas que no están en Base Estudiantes | C12: =COUNTIFS(tblMatriculas[Estado],"activa",tblMatriculas[En Base Estudiantes],"No") -> 5 | D12: Base Estudiantes no refleja traslados recientes | E12: Actualizar Base Estudiantes (ver lista abajo)
B13: Registros de Base Estudiantes que no están en Estudiantes | C13: {=SUMPRODUCT(--(COUNTIFS(tblMatriculas[Cédula],tblBase[Documento],tblMatriculas[Código],tblBase[Código grupo])=0))} -> 3 | D13: Estudiante figura en un grupo en el que ya no está | E13: Actualizar el grupo en Base Estudiantes (ver lista abajo)
B14: Nombres con espacios dobles o sobrantes | C14: {=SUMPRODUCT(--(tblMatriculas[Nombre]<>TRIM(tblMatriculas[Nombre])))} -> 585 | D14: Dificulta búsquedas exactas (la búsqueda de la ficha tolera esto parcialmente) | E14: Limpiar en la plataforma de origen (no se modificó aquí)
B15: Resumen por grupo' contiene valores fijos | C15: ="1 hoja" -> 1 hoja | D15: No se actualiza al cambiar los datos | E15: Usar GRUPOS/CURSOS, que son dinámicos
B18: A. Matrículas activas en Estudiantes que NO están en Base Estudiantes | I18: B. Registros de Base Estudiantes que NO están en Estudiantes
B19: Cédula | C19: Nombre | D19: Grupo | E19: Clases | F19: Observación | G19: Grupo(s) en Base | I19: Documento | J19: Nombre | K19: Grupo en Base | L19: Grupo(s) activos en Estudiantes
B20: {=_xlfn.LET(_xlpm.k,(tblMatriculas[Estado]="activa")*(tblMatriculas[En Base Estudiantes]="No"),_xlpm.res,_xlfn._xlws.FILTER(_xlfn.HSTACK(tblMatriculas[Cédula],tblMatriculas[Nombre],tblMatriculas[Código],tblMatriculas[Clases],tblMatriculas[Observación]),_xlpm.k,"Ninguna"),IFERROR(_xlfn.HSTACK(_xlpm.res,_xlfn.MAP(_xlfn.CHOOSECOLS(_xlpm.res,1),_xlfn.LAMBDA(_xlpm.x,_xlfn.TEXTJOIN(", ",TRUE,_xlfn._xlws.FILTER(tblBase[Código grupo],tblBase[Documento]=_xlpm.x,"—"))))),_xlpm.res))} -> 98561761 | C20: FRANCISCO JAVIER HERNANDEZ GARZON | D20: IAA-01 | E20: null/null | G20: MAR-02 | I20: {=_xlfn.LET(_xlpm.k,COUNTIFS(tblMatriculas[Cédula],tblBase[Documento],tblMatriculas[Código],tblBase[Código grupo])=0,_xlpm.res,_xlfn._xlws.FILTER(_xlfn.HSTACK(tblBase[Documento],tblBase[Nombre],tblBase[Código grupo]),_xlpm.k,"Ninguno"),IFERROR(_xlfn.HSTACK(_xlpm.res,_xlfn.MAP(_xlfn.CHOOSECOLS(_xlpm.res,1),_xlfn.LAMBDA(_xlpm.x,_xlfn.TEXTJOIN(", ",TRUE,_xlfn._xlws.FILTER(tblMatriculas[Código],(tblMatriculas[Cédula]=_xlpm.x)*(tblMatriculas[Estado]="activa"),"—"))))),_xlpm.res))} -> 1128391817 | J20: JOHAN ALEXIS ARANGO RUEDA | K20: IAA-08 | L20: IAA-09
B21: 1128391817 | C21: JOHAN ALEXIS ARANGO RUEDA | D21: IAA-09 | E21: 1/30 | F21: Traslado desde IAA-08 | G21: IAA-08 | I21: 43634807 | J21: MARILENY MAZO MAZO | K21: IAA-11 | L21: IAA-10
B22: 43634807 | C22: MARILENY MAZO MAZO | D22: IAA-10 | E22: 0/30 | F22: Traslado desde IAA-11 | G22: IAA-11 | I22: 1045110864 | J22: LEIDY JICETH OSPINA RUIZ | K22: IAA-12 | L22: IAA-11
B23: 1045110864 | C23: LEIDY JICETH OSPINA RUIZ | D23: IAA-11 | E23: 5/70 | F23: Traslado desde IAA-12 | G23: IAA-12
B24: 1017129750 | C24: ISABEL CRISTINA LÓPEZ ROJAS | D24: COM-02 | E24: 4/30 | G24: COM-04
B30: C. Activos sin registro de asistencia (null/null) y usuarios de prueba
B31: Cédula | C31: Nombre | D31: Grupo | E31: Clases | F31: Nivel
B32: {=_xlfn._xlws.FILTER(_xlfn.HSTACK(tblMatriculas[Cédula],tblMatriculas[Nombre],tblMatriculas[Código],tblMatriculas[Clases],tblMatriculas[Nivel]),(tblMatriculas[Nivel]="⚪ SIN REGISTRO")+(tblMatriculas[Nivel]="Prueba"),"Ninguno")} -> 98561761 | C32: FRANCISCO JAVIER HERNANDEZ GARZON | D32: IAA-01 | E32: null/null | F32: ⚪ SIN REGISTRO
B33: 1017164318 | C33: ESTEFANIA ZAPATA MORA | D33: IAA-02 | E33: null/null | F33: ⚪ SIN REGISTRO
B34: 1033258988 | C34: JUAN PABLO ALVAREZ VELEZ | D34: IAA-02 | E34: null/null | F34: ⚪ SIN REGISTRO
B35: 1017123176 | C35: JUAN CAMILO ZAPATA RAMIREZ | D35: IAA-02 | E35: null/null | F35: ⚪ SIN REGISTRO
B36: 79724557 | C36: LEONARDO VARGAS BRAVO | D36: IAA-02 | E36: null/null | F36: ⚪ SIN REGISTRO
B37: 71781407 | C37: RICHARD RICHARD BERMUDEZ YEPES | D37: IAA-02 | E37: null/null | F37: ⚪ SIN REGISTRO
B38: 43755572 | C38: SANDRA PATRICIA RIAZA ECHAVARRIA | D38: IAA-02 | E38: null/null | F38: ⚪ SIN REGISTRO
B39: 1015067077 | C39: PAULINA LEYLA SEPULVEDA URREGO | D39: IAA-02 | E39: null/null | F39: ⚪ SIN REGISTRO
B40: 43622109 | C40: LUZ ESTELA TABORDA GUTIERREZ | D40: IAA-02 | E40: null/null | F40: ⚪ SIN REGISTRO
B41: 43641448 | C41: LYNDA LUCIA CARTER FERNANDEZ | D41: IAA-02 | E41: null/null | F41: ⚪ SIN REGISTRO
B42: 35852104 | C42: NIDIA CHIRLEY RENTERIA ASPRILLA | D42: IAA-02 | E42: null/null | F42: ⚪ SIN REGISTRO
B43: 1021924663 | C43: SAMUEL CEBALLOS GONZALEZ | D43: IAA-02 | E43: null/null | F43: ⚪ SIN REGISTRO
B44: 22041587 | C44: MILEIDI EUGENIA CARVAJAL VELILLA | D44: IAA-02 | E44: null/null | F44: ⚪ SIN REGISTRO
... B83: 43515191 | C83: Usuario de Prueba | D83: MAR-07 | E83: 2/60 | F83: Prueba

Sheet DATOS
A1: DATOS — Registro diario de asistencia (plantilla). Una fila = un estudiante + un grupo + una fecha + un estado. Pegue aquí los registros diarios a partir de la fila 4.
A2: Actualmente vacía: el archivo original no contiene fechas de asistencia. Al llenarla se activan: historial, faltas consecutivas, última asistencia/inasistencia, tendencia y análisis por fecha.
A3: Fecha | B3: Código grupo | C3: Cédula | D3: Estudiante | E3: Estado | F3: Observación | H3: ¿POR QUÉ ESTÁ VACÍA? Esta hoja es la plantilla para el REGISTRO DIARIO de asistencia. El archivo original no trae la fecha de cada clase (solo acumulados como 4/45), y no se inventan datos. CÓMO USARLA: exporte de la plataforma el detalle por clase y pegue desde la fila 4: Fecha | Código grupo (ej. DAT-01) | Cédula | Estudiante | Estado (Presente / Ausente / Justificada / Tarde) Al pegarlo se activan solos: faltas consecutivas y tendencia en ALERTAS, e historial en FICHA ESTUDIANTE.

Sheet Estudiantes
A1: Cédula | B1: Nombre | C1: Estado | D1: Grupo | E1: Código | F1: Horario | G1: Asistencia | H1: Clases | I1: Programa | J1: Docente | K1: Observación | L1: Asistidas | M1: Clases planeadas | N1: Clases dictadas | O1: Inasistencias | P1: % asistencia | Q1: Incluir | R1: Nivel | S1: Última asistencia | T1: Última inasistencia | U1: Faltas consecutivas | V1: Tendencia | W1: Tipo de alerta | X1: Prioridad | Y1: En Base Estudiantes | Z1: Fecha matrícula
A2: 1013340045 | B2: ANGIE LORENA HENAO BARRETO | C2: activa | D2: DAT-01 - Análisis y Visualización de Datos | E2: DAT-01 | F2: Martes 12:00-14:00 | Miércoles 12:00-14:00 | Jueves 12:00-14:00 | G2: 0.089 | H2: 4/45 | I2: ANÁLISIS Y VISUALIZACIÓN DE DATOS PARA LA TOMA DE DECISIONES | J2: Carlos Duran | K2: Traslado desde DAT-09 | L2: =IFERROR(VALUE(LEFT(tblMatriculas[[#This Row],[Clases]],FIND("/",tblMatriculas[[#This Row],[Clases]])-1)),"") -> 4 | M2: =IFERROR(VALUE(MID(tblMatriculas[[#This Row],[Clases]],FIND("/",tblMatriculas[[#This Row],[Clases]])+1,5)),"") -> 45 | N2: =IF(tblMatriculas[[#This Row],[Asistidas]]="","",_xlfn.LET(_xlpm.c,_xlfn.XLOOKUP(tblMatriculas[[#This Row],[Código]],tblGrupos[Código],tblGrupos[Clases dictadas],0),_xlpm.bp,_xlfn.XLOOKUP(tblMatriculas[[#This Row],[Código]],tblGrupos[Código],tblGrupos[Clases planeadas],0),_xlpm.o,IF(LEFT(tblMatriculas[[#This Row],[Observación]],15)="Traslado desde ",TRIM(MID(tblMatriculas[[#This Row],[Observación]],16,20)),""),_xlpm.od,IF(_xlpm.o="",0,_xlfn.XLOOKUP(_xlpm.o,tblGrupos[Código],tblGrupos[Clases dictadas],0)),IF(OR(_xlpm.bp=0,tblMatriculas[[#This Row],[Clases planeadas]]<=_xlpm.bp),_xlpm.c,IF(_xlpm.od>0,_xlpm.c+_xlpm.od,ROUND(_xlpm.c*tblMatriculas[[#This Row],[Clases planeadas]]/_xlpm.bp,0))))) -> 9 | O2: =IF(OR(tblMatriculas[[#This Row],[Estado]]<>"activa",tblMatriculas[[#This Row],[Clases dictadas]]=""),"",MAX(0,tblMatriculas[[#This Row],[Clases dictadas]]-tblMatriculas[[#This Row],[Asistidas]])) -> 5 | P2: =IF(OR(tblMatriculas[[#This Row],[Estado]]<>"activa",tblMatriculas[[#This Row],[Asistidas]]=""),"",tblMatriculas[[#This Row],[Asistencia]]) -> 0.089 | Q2: =AND(tblMatriculas[[#This Row],[Estado]]="activa",ISNUMBER(tblMatriculas[[#This Row],[% asistencia]]),NOT(ISNUMBER(SEARCH(pPrueba,tblMatriculas[[#This Row],[Nombre]])))) -> TRUE | R2: =IF(tblMatriculas[[#This Row],[Estado]]<>"activa","Retirado",IF(ISNUMBER(SEARCH(pPrueba,tblMatriculas[[#This Row],[Nombre]])),"Prueba",IF(tblMatriculas[[#This Row],[% asistencia]]="","⚪ SIN REGISTRO",_xlfn.XLOOKUP(ROUND(tblMatriculas[[#This Row],[% asistencia]],3),tblNiveles[Hasta (% asistencia, incluido)],tblNiveles[Nivel],,1)))) -> 🟢 NORMAL | S2: {=_xlfn.LET(_xlpm.m,MAX(_xlfn.MAXIFS(tblAsistenciaDiaria[Fecha],tblAsistenciaDiaria[Cédula],tblMatriculas[[#This Row],[Cédula]],tblAsistenciaDiaria[Código grupo],tblMatriculas[[#This Row],[Código]],tblAsistenciaDiaria[Estado],{"Presente","Tarde"})),IF(_xlpm.m=0,"",_xlpm.m))} | T2: {=_xlfn.LET(_xlpm.m,MAX(_xlfn.MAXIFS(tblAsistenciaDiaria[Fecha],tblAsistenciaDiaria[Cédula],tblMatriculas[[#This Row],[Cédula]],tblAsistenciaDiaria[Código grupo],tblMatriculas[[#This Row],[Código]],tblAsistenciaDiaria[Estado],{"Ausente","Justificada"})),IF(_xlpm.m=0,"",_xlpm.m))} | U2: {=IF(COUNT(tblAsistenciaDiaria[Fecha])=0,"",IF(tblMatriculas[[#This Row],[Última inasistencia]]="",0,SUM(COUNTIFS(tblAsistenciaDiaria[Cédula],tblMatriculas[[#This Row],[Cédula]],tblAsistenciaDiaria[Código grupo],tblMatriculas[[#This Row],[Código]],tblAsistenciaDiaria[Fecha],">"&N(tblMatriculas[[#This Row],[Última asistencia]]),tblAsistenciaDiaria[Estado],{"Ausente","Justificada"}))))} | V2: {=_xlfn.LET(_xlpm.h,MAX(tblAsistenciaDiaria[Fecha]),_xlpm.w,pVentanaTend,_xlpm.c,tblMatriculas[[#This Row],[Cédula]],_xlpm.g,tblMatriculas[[#This Row],[Código]],_xlpm.F,tblAsistenciaDiaria[Fecha],_xlpm.pr,SUM(COUNTIFS(tblAsistenciaDiaria[Cédula],_xlpm.c,tblAsistenciaDiaria[Código grupo],_xlpm.g,_xlpm.F,">"&_xlpm.h-_xlpm.w,tblAsistenciaDiaria[Estado],{"Presente","Tarde"})),_xlpm.tr,COUNTIFS(tblAsistenciaDiaria[Cédula],_xlpm.c,tblAsistenciaDiaria[Código grupo],_xlpm.g,_xlpm.F,">"&_xlpm.h-_xlpm.w),_xlpm.pp,SUM(COUNTIFS(tblAsistenciaDiaria[Cédula],_xlpm.c,tblAsistenciaDiaria[Código grupo],_xlpm.g,_xlpm.F,">"&_xlpm.h-2*_xlpm.w,_xlpm.F,"<="&_xlpm.h-_xlpm.w,tblAsistenciaDiaria[Estado],{"Presente","Tarde"})),_xlpm.tp,COUNTIFS(tblAsistenciaDiaria[Cédula],_xlpm.c,tblAsistenciaDiaria[Código grupo],_xlpm.g,_xlpm.F,">"&_xlpm.h-2*_xlpm.w,_xlpm.F,"<="&_xlpm.h-_xlpm.w),IF(OR(_xlpm.tr=0,_xlpm.tp=0),"",IF(_xlpm.pp/_xlpm.tp-_xlpm.pr/_xlpm.tr>=pCaidaTend,"📉 Negativa",IF(_xlpm.pr/_xlpm.tr-_xlpm.pp/_xlpm.tp>=pCaidaTend,"📈 Positiva","➖ Estable"))))} | W2: {=IF(OR(tblMatriculas[[#This Row],[Nivel]]="Retirado",tblMatriculas[[#This Row],[Nivel]]="Prueba"),"",_xlfn.TEXTJOIN(" + ",TRUE,IF(OR(tblMatriculas[[#This Row],[Nivel]]=INDEX(tblNiveles[Nivel],{1,2,3})),tblMatriculas[[#This Row],[Nivel]],""),IF(tblMatriculas[[#This Row],[Nivel]]="⚪ SIN REGISTRO","⚪ SIN REGISTRO",""),IF(N(tblMatriculas[[#This Row],[Faltas consecutivas]])>=pFaltasConsec,"⚠️ AUSENCIAS CONSECUTIVAS",""),IF(tblMatriculas[[#This Row],[Tendencia]]="📉 Negativa","📉 TENDENCIA NEGATIVA","")))} | X2: =IF(tblMatriculas[[#This Row],[Tipo de alerta]]="","",MIN(IFERROR(_xlfn.XLOOKUP(tblMatriculas[[#This Row],[Nivel]],tblNiveles[Nivel],tblNiveles[Prioridad]),9),IF(tblMatriculas[[#This Row],[Nivel]]="⚪ SIN REGISTRO",2.5,9),IF(N(tblMatriculas[[#This Row],[Faltas consecutivas]])>=pFaltasConsec,1.5,9),IF(tblMatriculas[[#This Row],[Tendencia]]="📉 Negativa",3.5,9))) | Y2: =IF(COUNTIFS('Base Estudiantes'!$C:$C,tblMatriculas[[#This Row],[Cédula]],'Base Estudiantes'!$I:$I,tblMatriculas[[#This Row],[Código]])>0,"Sí","No") -> Sí | Z2: {=_xlfn.XLOOKUP(tblMatriculas[[#This Row],[Cédula]]&"|"&tblMatriculas[[#This Row],[Código]],tblBase[Documento]&"|"&tblBase[Código grupo],tblBase[Fecha matrícula],"")} -> 46263
